Workbook
Name LiborTenor: ForwardLiborSimulation!$E$3
Name TimeStep: ForwardLiborSimulation!$E$2

Sheet ForwardLiborSimulation
D2: Time Step | E2: =1/12/1 -> 0.083333333 | F2: <- 1month
D3: Libor Tenor | E3: 0.25 | F3: <- 3month | H3: Simulated Forward Libor Curve
G4: Initial
E5: Initial | G5: Forward Libor
D6: Maturity (in years) | E6: Discount Factor | F6: =+F47 -> t (years) = | G6: =+G47 -> 0 | H6: =+H47 -> 0.083333333 | I6: =+I47 -> 0.16666667 | J6: =+J47 -> 0.25 | K6: =+K47 -> 0.33333333 | L6: =+L47 -> 0.41666667 | M6: =+M47 -> 0.5 | ... DW6: =+DW47 -> 10
D7: =+D8+$E$3 -> 10 | E7: =+E8/(1+(D7-D8)*G7) -> 0.62440567 | F7: =+"L(t;"&D8&","&D7&")" -> L(t;9.75,10) | G7: 0.05 | H7: =+G7+G7*Volatility!G7*(-DriftSum!H7*TimeStep+SQRT(TimeStep)*H$49) -> 0.050874068 | I7: =+H7+H7*Volatility!H7*(-DriftSum!I7*TimeStep+SQRT(TimeStep)*I$49) -> 0.05093397 | J7: =+I7+I7*Volatility!I7*(-DriftSum!J7*TimeStep+SQRT(TimeStep)*J$49) -> 0.050090072 | K7: =+J7+J7*Volatility!J7*(-DriftSum!K7*TimeStep+SQRT(TimeStep)*K$49) -> 0.050387196 | L7: =+K7+K7*Volatility!K7*(-DriftSum!L7*TimeStep+SQRT(TimeStep)*L$49) -> 0.049437445 | M7: =+L7+L7*Volatility!L7*(-DriftSum!M7*TimeStep+SQRT(TimeStep)*M$49) -> 0.051456836 | N7: =+M7+M7*Volatility!M7*(-DriftSum!N7*TimeStep+SQRT(TimeStep)*N$49) -> 0.051154898 | O7: =+N7+N7*Volatility!N7*(-DriftSum!O7*TimeStep+SQRT(TimeStep)*O$49) -> 0.052316916 | ... DT7: =+DS7+DS7*Volatility!DS7*(-DriftSum!DT7*TimeStep+SQRT(TimeStep)*DT$49) -> 0.062346112
D8: =+D9+$E$3 -> 9.75 | E8: =+E9/(1+(D8-D9)*G8) -> 0.63221074 | F8: =+"L(t;"&D9&","&D8&")" -> L(t;9.5,9.75) | G8: 0.05 | H8: =+G8+G8*Volatility!G8*(-DriftSum!H8*TimeStep+SQRT(TimeStep)*H$49) -> 0.050911815 | I8: =+H8+H8*Volatility!H8*(-DriftSum!I8*TimeStep+SQRT(TimeStep)*I$49) -> 0.050974059 | J8: =+I8+I8*Volatility!I8*(-DriftSum!J8*TimeStep+SQRT(TimeStep)*J$49) -> 0.050093531 | K8: =+J8+J8*Volatility!J8*(-DriftSum!K8*TimeStep+SQRT(TimeStep)*K$49) -> 0.050402959 | L8: =+K8+K8*Volatility!K8*(-DriftSum!L8*TimeStep+SQRT(TimeStep)*L$49) -> 0.049412493 | M8: =+L8+L8*Volatility!L8*(-DriftSum!M8*TimeStep+SQRT(TimeStep)*M$49) -> 0.051515884 | N8: =+M8+M8*Volatility!M8*(-DriftSum!N8*TimeStep+SQRT(TimeStep)*N$49) -> 0.05120054 | O8: =+N8+N8*Volatility!N8*(-DriftSum!O8*TimeStep+SQRT(TimeStep)*O$49) -> 0.052412456 | ... CJ8: =+CI8+CI8*Volatility!CI8*(-DriftSum!CJ8*TimeStep+SQRT(TimeStep)*CJ$49) -> 0.053040034 | CK8: =+CJ8-CJ8*Volatility!CJ8*DriftSum!CK8*TimeStep+Volatility!CJ8*CJ8*SQRT(TimeStep)*CK$49 -> 0.052616977 | CL8: =+CK8-CK8*Volatility!CK8*DriftSum!CL8*TimeStep+Volatility!CK8*CK8*SQRT(TimeStep)*CL$49 -> 0.053608968 | CM8: =+CL8-CL8*Volatility!CL8*DriftSum!CM8*TimeStep+Volatility!CL8*CL8*SQRT(TimeStep)*CM$49 -> 0.053063111 | CN8: =+CM8-CM8*Volatility!CM8*DriftSum!CN8*TimeStep+Volatility!CM8*CM8*SQRT(TimeStep)*CN$49 -> 0.052411643 | CO8: =+CN8-CN8*Volatility!CN8*DriftSum!CO8*TimeStep+Volatility!CN8*CN8*SQRT(TimeStep)*CO$49 -> 0.050468274 | CP8: =+CO8-CO8*Volatility!CO8*DriftSum!CP8*TimeStep+Volatility!CO8*CO8*SQRT(TimeStep)*CP$49 -> 0.051164108 | CQ8: =+CP8-CP8*Volatility!CP8*DriftSum!CQ8*TimeStep+Volatility!CP8*CP8*SQRT(TimeStep)*CQ$49 -> 0.052450929 | CR8: =+CQ8-CQ8*Volatility!CQ8*DriftSum!CR8*TimeStep+Volatility!CQ8*CQ8*SQRT(TimeStep)*CR$49 -> 0.053645155 | ... DQ8: =+DP8-DP8*Volatility!DP8*DriftSum!DQ8*TimeStep+Volatility!DP8*DP8*SQRT(TimeStep)*DQ$49 -> 0.062621978
D9: =+D10+$E$3 -> 9.5 | E9: =+E10/(1+(D9-D10)*G9) -> 0.64011337 | F9: =+"L(t;"&D10&","&D9&")" -> L(t;9.25,9.5) | G9: 0.05 | H9: =+G9+G9*Volatility!G9*(-DriftSum!H9*TimeStep+SQRT(TimeStep)*H$49) -> 0.05094953 | I9: =+H9+H9*Volatility!H9*(-DriftSum!I9*TimeStep+SQRT(TimeStep)*I$49) -> 0.051014083 | J9: =+I9+I9*Volatility!I9*(-DriftSum!J9*TimeStep+SQRT(TimeStep)*J$49) -> 0.050096834 | K9: =+J9+J9*Volatility!J9*(-DriftSum!K9*TimeStep+SQRT(TimeStep)*K$49) -> 0.050418533 | L9: =+K9+K9*Volatility!K9*(-DriftSum!L9*TimeStep+SQRT(TimeStep)*L$49) -> 0.049387297 | M9: =+L9+L9*Volatility!L9*(-DriftSum!M9*TimeStep+SQRT(TimeStep)*M$49) -> 0.051574559 | N9: =+M9+M9*Volatility!M9*(-DriftSum!N9*TimeStep+SQRT(TimeStep)*N$49) -> 0.051245746 | O9: =+N9+N9*Volatility!N9*(-DriftSum!O9*TimeStep+SQRT(TimeStep)*O$49) -> 0.052507599 | ... CJ9: =+CI9+CI9*Volatility!CI9*(-DriftSum!CJ9*TimeStep+SQRT(TimeStep)*CJ$49) -> 0.053093786 | CK9: =+CJ9-CJ9*Volatility!CJ9*DriftSum!CK9*TimeStep+Volatility!CJ9*CJ9*SQRT(TimeStep)*CK$49 -> 0.052652802 | CL9: =+CK9-CK9*Volatility!CK9*DriftSum!CL9*TimeStep+Volatility!CK9*CK9*SQRT(TimeStep)*CL$49 -> 0.053685387 | CM9: =+CL9-CL9*Volatility!CL9*DriftSum!CM9*TimeStep+Volatility!CL9*CL9*SQRT(TimeStep)*CM$49 -> 0.053116254 | CN9: =+CM9-CM9*Volatility!CM9*DriftSum!CN9*TimeStep+Volatility!CM9*CM9*SQRT(TimeStep)*CN$49 -> 0.052437366 | CO9: =+CN9-CN9*Volatility!CN9*DriftSum!CO9*TimeStep+Volatility!CN9*CN9*SQRT(TimeStep)*CO$49 -> 0.050413897 | CP9: =+CO9-CO9*Volatility!CO9*DriftSum!CP9*TimeStep+Volatility!CO9*CO9*SQRT(TimeStep)*CP$49 -> 0.051136862 | CQ9: =+CP9-CP9*Volatility!CP9*DriftSum!CQ9*TimeStep+Volatility!CP9*CP9*SQRT(TimeStep)*CQ$49 -> 0.052474832 | CR9: =+CQ9-CQ9*Volatility!CQ9*DriftSum!CR9*TimeStep+Volatility!CQ9*CQ9*SQRT(TimeStep)*CR$49 -> 0.053717716 | ... DN9: =+DM9-DM9*Volatility!DM9*DriftSum!DN9*TimeStep+Volatility!DM9*DM9*SQRT(TimeStep)*DN$49 -> 0.068087922
D10: =+D11+$E$3 -> 9.25 | E10: =+E11/(1+(D10-D11)*G10) -> 0.64811479 | F10: =+"L(t;"&D11&","&D10&")" -> L(t;9,9.25) | G10: 0.05 | H10: =+G10+G10*Volatility!G10*(-DriftSum!H10*TimeStep+SQRT(TimeStep)*H$49) -> 0.05098721 | I10: =+H10+H10*Volatility!H10*(-DriftSum!I10*TimeStep+SQRT(TimeStep)*I$49) -> 0.05105404 | J10: =+I10+I10*Volatility!I10*(-DriftSum!J10*TimeStep+SQRT(TimeStep)*J$49) -> 0.050099977 | K10: =+J10+J10*Volatility!J10*(-DriftSum!K10*TimeStep+SQRT(TimeStep)*K$49) -> 0.050433914 | L10: =+K10+K10*Volatility!K10*(-DriftSum!L10*TimeStep+SQRT(TimeStep)*L$49) -> 0.04936185 | M10: =+L10+L10*Volatility!L10*(-DriftSum!M10*TimeStep+SQRT(TimeStep)*M$49) -> 0.05163285 | N10: =+M10+M10*Volatility!M10*(-DriftSum!N10*TimeStep+SQRT(TimeStep)*N$49) -> 0.051290502 | O10: =+N10+N10*Volatility!N10*(-DriftSum!O10*TimeStep+SQRT(TimeStep)*O$49) -> 0.052602331 | ... CJ10: =+CI10+CI10*Volatility!CI10*(-DriftSum!CJ10*TimeStep+SQRT(TimeStep)*CJ$49) -> 0.053140541 | CK10: =+CJ10-CJ10*Volatility!CJ10*DriftSum!CK10*TimeStep+Volatility!CJ10*CJ10*SQRT(TimeStep)*CK$49 -> 0.052681615 | CL10: =+CK10-CK10*Volatility!CK10*DriftSum!CL10*TimeStep+Volatility!CK10*CK10*SQRT(TimeStep)*CL$49 -> 0.053754666 | CM10: =+CL10-CL10*Volatility!CL10*DriftSum!CM10*TimeStep+Volatility!CL10*CL10*SQRT(TimeStep)*CM$49 -> 0.053162231 | CN10: =+CM10-CM10*Volatility!CM10*DriftSum!CN10*TimeStep+Volatility!CM10*CM10*SQRT(TimeStep)*CN$49 -> 0.052455925 | CO10: =+CN10-CN10*Volatility!CN10*DriftSum!CO10*TimeStep+Volatility!CN10*CN10*SQRT(TimeStep)*CO$49 -> 0.050352527 | CP10: =+CO10-CO10*Volatility!CO10*DriftSum!CP10*TimeStep+Volatility!CO10*CO10*SQRT(TimeStep)*CP$49 -> 0.051102423 | CQ10: =+CP10-CP10*Volatility!CP10*DriftSum!CQ10*TimeStep+Volatility!CP10*CP10*SQRT(TimeStep)*CQ$49 -> 0.052491255 | CR10: =+CQ10-CQ10*Volatility!CQ10*DriftSum!CR10*TimeStep+Volatility!CQ10*CQ10*SQRT(TimeStep)*CR$49 -> 0.053782618 | ... DK10: =+DJ10-DJ10*Volatility!DJ10*DriftSum!DK10*TimeStep+Volatility!DJ10*DJ10*SQRT(TimeStep)*DK$49 -> 0.066295429
D11: =+D12+$E$3 -> 9 | E11: =+E12/(1+(D11-D12)*G11) -> 0.65621623 | F11: =+"L(t;"&D12&","&D11&")" -> L(t;8.75,9) | G11: 0.05 | H11: =+G11+G11*Volatility!G11*(-DriftSum!H11*TimeStep+SQRT(TimeStep)*H$49) -> 0.051024855 | I11: =+H11+H11*Volatility!H11*(-DriftSum!I11*TimeStep+SQRT(TimeStep)*I$49) -> 0.051093927 | J11: =+I11+I11*Volatility!I11*(-DriftSum!J11*TimeStep+SQRT(TimeStep)*J$49) -> 0.050102957 | K11: =+J11+J11*Volatility!J11*(-DriftSum!K11*TimeStep+SQRT(TimeStep)*K$49) -> 0.050449094 | L11: =+K11+K11*Volatility!K11*(-DriftSum!L11*TimeStep+SQRT(TimeStep)*L$49) -> 0.049336146 | M11: =+L11+L11*Volatility!L11*(-DriftSum!M11*TimeStep+SQRT(TimeStep)*M$49) -> 0.051690749 | N11: =+M11+M11*Volatility!M11*(-DriftSum!N11*TimeStep+SQRT(TimeStep)*N$49) -> 0.0513348 | O11: =+N11+N11*Volatility!N11*(-DriftSum!O11*TimeStep+SQRT(TimeStep)*O$49) -> 0.052696637 | ... CJ11: =+CI11+CI11*Volatility!CI11*(-DriftSum!CJ11*TimeStep+SQRT(TimeStep)*CJ$49) -> 0.053180135 | CK11: =+CJ11-CJ11*Volatility!CJ11*DriftSum!CK11*TimeStep+Volatility!CJ11*CJ11*SQRT(TimeStep)*CK$49 -> 0.052703258 | CL11: =+CK11-CK11*Volatility!CK11*DriftSum!CL11*TimeStep+Volatility!CK11*CK11*SQRT(TimeStep)*CL$49 -> 0.053816627 | CM11: =+CL11-CL11*Volatility!CL11*DriftSum!CM11*TimeStep+Volatility!CL11*CL11*SQRT(TimeStep)*CM$49 -> 0.053200872 | CN11: =+CM11-CM11*Volatility!CM11*DriftSum!CN11*TimeStep+Volatility!CM11*CM11*SQRT(TimeStep)*CN$49 -> 0.052467161 | CO11: =+CN11-CN11*Volatility!CN11*DriftSum!CO11*TimeStep+Volatility!CN11*CN11*SQRT(TimeStep)*CO$49 -> 0.050284042 | CP11: =+CO11-CO11*Volatility!CO11*DriftSum!CP11*TimeStep+Volatility!CO11*CO11*SQRT(TimeStep)*CP$49 -> 0.051060655 | CQ11: =+CP11-CP11*Volatility!CP11*DriftSum!CQ11*TimeStep+Volatility!CP11*CP11*SQRT(TimeStep)*CQ$49 -> 0.052500034 | CR11: =+CQ11-CQ11*Volatility!CQ11*DriftSum!CR11*TimeStep+Volatility!CQ11*CQ11*SQRT(TimeStep)*CR$49 -> 0.053839671 | ... DH11: =+DG11-DG11*Volatility!DG11*DriftSum!DH11*TimeStep+Volatility!DG11*DG11*SQRT(TimeStep)*DH$49 -> 0.066624939
D12: =+D13+$E$3 -> 8.75 | E12: =+E13/(1+(D12-D13)*G12) -> 0.66441893 | F12: =+"L(t;"&D13&","&D12&")" -> L(t;8.5,8.75) | G12: 0.05 | H12: =+G12+G12*Volatility!G12*(-DriftSum!H12*TimeStep+SQRT(TimeStep)*H$49) -> 0.051062462 | I12: =+H12+H12*Volatility!H12*(-DriftSum!I12*TimeStep+SQRT(TimeStep)*I$49) -> 0.051133741 | J12: =+I12+I12*Volatility!I12*(-DriftSum!J12*TimeStep+SQRT(TimeStep)*J$49) -> 0.050105769 | K12: =+J12+J12*Volatility!J12*(-DriftSum!K12*TimeStep+SQRT(TimeStep)*K$49) -> 0.050464068 | L12: =+K12+K12*Volatility!K12*(-DriftSum!L12*TimeStep+SQRT(TimeStep)*L$49) -> 0.049310177 | M12: =+L12+L12*Volatility!L12*(-DriftSum!M12*TimeStep+SQRT(TimeStep)*M$49) -> 0.051748244 | N12: =+M12+M12*Volatility!M12*(-DriftSum!N12*TimeStep+SQRT(TimeStep)*N$49) -> 0.051378627 | O12: =+N12+N12*Volatility!N12*(-DriftSum!O12*TimeStep+SQRT(TimeStep)*O$49) -> 0.052790505 | ... CJ12: =+CI12+CI12*Volatility!CI12*(-DriftSum!CJ12*TimeStep+SQRT(TimeStep)*CJ$49) -> 0.053212403 | CK12: =+CJ12-CJ12*Volatility!CJ12*DriftSum!CK12*TimeStep+Volatility!CJ12*CJ12*SQRT(TimeStep)*CK$49 -> 0.052717576 | CL12: =+CK12-CK12*Volatility!CK12*DriftSum!CL12*TimeStep+Volatility!CK12*CK12*SQRT(TimeStep)*CL$49 -> 0.053871092 | CM12: =+CL12-CL12*Volatility!CL12*DriftSum!CM12*TimeStep+Volatility!CL12*CL12*SQRT(TimeStep)*CM$49 -> 0.053232009 | CN12: =+CM12-CM12*Volatility!CM12*DriftSum!CN12*TimeStep+Volatility!CM12*CM12*SQRT(TimeStep)*CN$49 -> 0.052470918 | CO12: =+CN12-CN12*Volatility!CN12*DriftSum!CO12*TimeStep+Volatility!CN12*CN12*SQRT(TimeStep)*CO$49 -> 0.050208325 | CP12: =+CO12-CO12*Volatility!CO12*DriftSum!CP12*TimeStep+Volatility!CO12*CO12*SQRT(TimeStep)*CP$49 -> 0.051011427 | CQ12: =+CP12-CP12*Volatility!CP12*DriftSum!CQ12*TimeStep+Volatility!CP12*CP12*SQRT(TimeStep)*CQ$49 -> 0.052501011 | CR12: =+CQ12-CQ12*Volatility!CQ12*DriftSum!CR12*TimeStep+Volatility!CQ12*CQ12*SQRT(TimeStep)*CR$49 -> 0.05388869 | ... DE12: =+DD12-DD12*Volatility!DD12*DriftSum!DE12*TimeStep+Volatility!DD12*DD12*SQRT(TimeStep)*DE$49 -> 0.064777876
D13: =+D14+$E$3 -> 8.5 | E13: =+E14/(1+(D13-D14)*G13) -> 0.67272416 | F13: =+"L(t;"&D14&","&D13&")" -> L(t;8.25,8.5) | G13: 0.05 | H13: =+G13+G13*Volatility!G13*(-DriftSum!H13*TimeStep+SQRT(TimeStep)*H$49) -> 0.051100031 | I13: =+H13+H13*Volatility!H13*(-DriftSum!I13*TimeStep+SQRT(TimeStep)*I$49) -> 0.051173479 | J13: =+I13+I13*Volatility!I13*(-DriftSum!J13*TimeStep+SQRT(TimeStep)*J$49) -> 0.050108409 | K13: =+J13+J13*Volatility!J13*(-DriftSum!K13*TimeStep+SQRT(TimeStep)*K$49) -> 0.050478831 | L13: =+K13+K13*Volatility!K13*(-DriftSum!L13*TimeStep+SQRT(TimeStep)*L$49) -> 0.049283937 | M13: =+L13+L13*Volatility!L13*(-DriftSum!M13*TimeStep+SQRT(TimeStep)*M$49) -> 0.051805328 | N13: =+M13+M13*Volatility!M13*(-DriftSum!N13*TimeStep+SQRT(TimeStep)*N$49) -> 0.051421973 | O13: =+N13+N13*Volatility!N13*(-DriftSum!O13*TimeStep+SQRT(TimeStep)*O$49) -> 0.052883919 | ... CJ13: =+CI13+CI13*Volatility!CI13*(-DriftSum!CJ13*TimeStep+SQRT(TimeStep)*CJ$49) -> 0.053237186 | CK13: =+CJ13-CJ13*Volatility!CJ13*DriftSum!CK13*TimeStep+Volatility!CJ13*CJ13*SQRT(TimeStep)*CK$49 -> 0.052724413 | CL13: =+CK13-CK13*Volatility!CK13*DriftSum!CL13*TimeStep+Volatility!CK13*CK13*SQRT(TimeStep)*CL$49 -> 0.053917885 | CM13: =+CL13-CL13*Volatility!CL13*DriftSum!CM13*TimeStep+Volatility!CL13*CL13*SQRT(TimeStep)*CM$49 -> 0.053255478 | CN13: =+CM13-CM13*Volatility!CM13*DriftSum!CN13*TimeStep+Volatility!CM13*CM13*SQRT(TimeStep)*CN$49 -> 0.052467044 | CO13: =+CN13-CN13*Volatility!CN13*DriftSum!CO13*TimeStep+Volatility!CN13*CN13*SQRT(TimeStep)*CO$49 -> 0.050125263 | CP13: =+CO13-CO13*Volatility!CO13*DriftSum!CP13*TimeStep+Volatility!CO13*CO13*SQRT(TimeStep)*CP$49 -> 0.050954608 | CQ13: =+CP13-CP13*Volatility!CP13*DriftSum!CQ13*TimeStep+Volatility!CP13*CP13*SQRT(TimeStep)*CQ$49 -> 0.052494028 | CR13: =+CQ13-CQ13*Volatility!CQ13*DriftSum!CR13*TimeStep+Volatility!CQ13*CQ13*SQRT(TimeStep)*CR$49 -> 0.053929489 | ... DB13: =+DA13-DA13*Volatility!DA13*DriftSum!DB13*TimeStep+Volatility!DA13*DA13*SQRT(TimeStep)*DB$49 -> 0.062917972
D14: =+D15+$E$3 -> 8.25 | E14: =+E15/(1+(D14-D15)*G14) -> 0.68113322 | F14: =+"L(t;"&D15&","&D14&")" -> L(t;8,8.25) | G14: 0.05 | H14: =+G14+G14*Volatility!G14*(-DriftSum!H14*TimeStep+SQRT(TimeStep)*H$49) -> 0.051137561 | I14: =+H14+H14*Volatility!H14*(-DriftSum!I14*TimeStep+SQRT(TimeStep)*I$49) -> 0.051213137 | J14: =+I14+I14*Volatility!I14*(-DriftSum!J14*TimeStep+SQRT(TimeStep)*J$49) -> 0.050110871 | K14: =+J14+J14*Volatility!J14*(-DriftSum!K14*TimeStep+SQRT(TimeStep)*K$49) -> 0.050493375 | L14: =+K14+K14*Volatility!K14*(-DriftSum!L14*TimeStep+SQRT(TimeStep)*L$49) -> 0.049257419 | M14: =+L14+L14*Volatility!L14*(-DriftSum!M14*TimeStep+SQRT(TimeStep)*M$49) -> 0.051861989 | N14: =+M14+M14*Volatility!M14*(-DriftSum!N14*TimeStep+SQRT(TimeStep)*N$49) -> 0.051464826 | O14: =+N14+N14*Volatility!N14*(-DriftSum!O14*TimeStep+SQRT(TimeStep)*O$49) -> 0.052976865 | ... CJ14: =+CI14+CI14*Volatility!CI14*(-DriftSum!CJ14*TimeStep+SQRT(TimeStep)*CJ$49) -> 0.053254325 | CK14: =+CJ14-CJ14*Volatility!CJ14*DriftSum!CK14*TimeStep+Volatility!CJ14*CJ14*SQRT(TimeStep)*CK$49 -> 0.052723619 | CL14: =+CK14-CK14*Volatility!CK14*DriftSum!CL14*TimeStep+Volatility!CK14*CK14*SQRT(TimeStep)*CL$49 -> 0.053956835 | CM14: =+CL14-CL14*Volatility!CL14*DriftSum!CM14*TimeStep+Volatility!CL14*CL14*SQRT(TimeStep)*CM$49 -> 0.053271115 | CN14: =+CM14-CM14*Volatility!CM14*DriftSum!CN14*TimeStep+Volatility!CM14*CM14*SQRT(TimeStep)*CN$49 -> 0.052455387 | CO14: =+CN14-CN14*Volatility!CN14*DriftSum!CO14*TimeStep+Volatility!CN14*CN14*SQRT(TimeStep)*CO$49 -> 0.050034744 | CP14: =+CO14-CO14*Volatility!CO14*DriftSum!CP14*TimeStep+Volatility!CO14*CO14*SQRT(TimeStep)*CP$49 -> 0.050890074 | CQ14: =+CP14-CP14*Volatility!CP14*DriftSum!CQ14*TimeStep+Volatility!CP14*CP14*SQRT(TimeStep)*CQ$49 -> 0.052478932 | CR14: =+CQ14-CQ14*Volatility!CQ14*DriftSum!CR14*TimeStep+Volatility!CQ14*CQ14*SQRT(TimeStep)*CR$49 -> 0.05396189 | ... CY14: =+CX14-CX14*Volatility!CX14*DriftSum!CY14*TimeStep+Volatility!CX14*CX14*SQRT(TimeStep)*CY$49 -> 0.060547842
D15: =+D16+$E$3 -> 8 | E15: =+E16/(1+(D15-D16)*G15) -> 0.68964738 | F15: =+"L(t;"&D16&","&D15&")" -> L(t;7.75,8) | G15: 0.05 | H15: =+G15+G15*Volatility!G15*(-DriftSum!H15*TimeStep+SQRT(TimeStep)*H$49) -> 0.051175049 | I15: =+H15+H15*Volatility!H15*(-DriftSum!I15*TimeStep+SQRT(TimeStep)*I$49) -> 0.051252714 | J15: =+I15+I15*Volatility!I15*(-DriftSum!J15*TimeStep+SQRT(TimeStep)*J$49) -> 0.050113153 | K15: =+J15+J15*Volatility!J15*(-DriftSum!K15*TimeStep+SQRT(TimeStep)*K$49) -> 0.050507696 | L15: =+K15+K15*Volatility!K15*(-DriftSum!L15*TimeStep+SQRT(TimeStep)*L$49) -> 0.049230616 | M15: =+L15+L15*Volatility!L15*(-DriftSum!M15*TimeStep+SQRT(TimeStep)*M$49) -> 0.051918218 | N15: =+M15+M15*Volatility!M15*(-DriftSum!N15*TimeStep+SQRT(TimeStep)*N$49) -> 0.051507176 | O15: =+N15+N15*Volatility!N15*(-DriftSum!O15*TimeStep+SQRT(TimeStep)*O$49) -> 0.053069329 | ... CJ15: =+CI15+CI15*Volatility!CI15*(-DriftSum!CJ15*TimeStep+SQRT(TimeStep)*CJ$49) -> 0.053263664 | CK15: =+CJ15-CJ15*Volatility!CJ15*DriftSum!CK15*TimeStep+Volatility!CJ15*CJ15*SQRT(TimeStep)*CK$49 -> 0.052715047 | CL15: =+CK15-CK15*Volatility!CK15*DriftSum!CL15*TimeStep+Volatility!CK15*CK15*SQRT(TimeStep)*CL$49 -> 0.053987769 | CM15: =+CL15-CL15*Volatility!CL15*DriftSum!CM15*TimeStep+Volatility!CL15*CL15*SQRT(TimeStep)*CM$49 -> 0.05327876 | CN15: =+CM15-CM15*Volatility!CM15*DriftSum!CN15*TimeStep+Volatility!CM15*CM15*SQRT(TimeStep)*CN$49 -> 0.052435801 | CO15: =+CN15-CN15*Volatility!CN15*DriftSum!CO15*TimeStep+Volatility!CN15*CN15*SQRT(TimeStep)*CO$49 -> 0.049936663 | CP15: =+CO15-CO15*Volatility!CO15*DriftSum!CP15*TimeStep+Volatility!CO15*CO15*SQRT(TimeStep)*CP$49 -> 0.050817704 | CQ15: =+CP15-CP15*Volatility!CP15*DriftSum!CQ15*TimeStep+Volatility!CP15*CP15*SQRT(TimeStep)*CQ$49 -> 0.052455574 | CR15: =+CQ15-CQ15*Volatility!CQ15*DriftSum!CR15*TimeStep+Volatility!CQ15*CQ15*SQRT(TimeStep)*CR$49 -> 0.053985713 | ... CV15: =+CU15-CU15*Volatility!CU15*DriftSum!CV15*TimeStep+Volatility!CU15*CU15*SQRT(TimeStep)*CV$49 -> 0.056278602
D16: =+D17+$E$3 -> 7.75 | E16: =+E17/(1+(D16-D17)*G16) -> 0.69826797 | F16: =+"L(t;"&D17&","&D16&")" -> L(t;7.5,7.75) | G16: 0.05 | H16: =+G16+G16*Volatility!G16*(-DriftSum!H16*TimeStep+SQRT(TimeStep)*H$49) -> 0.051212495 | I16: =+H16+H16*Volatility!H16*(-DriftSum!I16*TimeStep+SQRT(TimeStep)*I$49) -> 0.051292205 | J16: =+I16+I16*Volatility!I16*(-DriftSum!J16*TimeStep+SQRT(TimeStep)*J$49) -> 0.050115249 | K16: =+J16+J16*Volatility!J16*(-DriftSum!K16*TimeStep+SQRT(TimeStep)*K$49) -> 0.050521787 | L16: =+K16+K16*Volatility!K16*(-DriftSum!L16*TimeStep+SQRT(TimeStep)*L$49) -> 0.049203522 | M16: =+L16+L16*Volatility!L16*(-DriftSum!M16*TimeStep+SQRT(TimeStep)*M$49) -> 0.051974006 | N16: =+M16+M16*Volatility!M16*(-DriftSum!N16*TimeStep+SQRT(TimeStep)*N$49) -> 0.051549011 | O16: =+N16+N16*Volatility!N16*(-DriftSum!O16*TimeStep+SQRT(TimeStep)*O$49) -> 0.053161295 | ... CJ16: =+CI16+CI16*Volatility!CI16*(-DriftSum!CJ16*TimeStep+SQRT(TimeStep)*CJ$49) -> 0.05326505 | CK16: =+CJ16-CJ16*Volatility!CJ16*DriftSum!CK16*TimeStep+Volatility!CJ16*CJ16*SQRT(TimeStep)*CK$49 -> 0.05269855 | CL16: =+CK16-CK16*Volatility!CK16*DriftSum!CL16*TimeStep+Volatility!CK16*CK16*SQRT(TimeStep)*CL$49 -> 0.054010521 | CM16: =+CL16-CL16*Volatility!CL16*DriftSum!CM16*TimeStep+Volatility!CL16*CL16*SQRT(TimeStep)*CM$49 -> 0.053278255 | CN16: =+CM16-CM16*Volatility!CM16*DriftSum!CN16*TimeStep+Volatility!CM16*CM16*SQRT(TimeStep)*CN$49 -> 0.052408142 | CO16: =+CN16-CN16*Volatility!CN16*DriftSum!CO16*TimeStep+Volatility!CN16*CN16*SQRT(TimeStep)*CO$49 -> 0.049830918 | CP16: =+CO16-CO16*Volatility!CO16*DriftSum!CP16*TimeStep+Volatility!CO16*CO16*SQRT(TimeStep)*CP$49 -> 0.050737379 | CQ16: =+CP16-CP16*Volatility!CP16*DriftSum!CQ16*TimeStep+Volatility!CP16*CP16*SQRT(TimeStep)*CQ$49 -> 0.052423808 | CR16: =+CQ16-CQ16*Volatility!CQ16*DriftSum!CR16*TimeStep+Volatility!CQ16*CQ16*SQRT(TimeStep)*CR$49 -> 0.054000784 | CS16: =+CR16-CR16*Volatility!CR16*DriftSum!CS16*TimeStep+Volatility!CR16*CR16*SQRT(TimeStep)*CS$49 -> 0.054747088
D17: =+D18+$E$3 -> 7.5 | E17: =+E18/(1+(D17-D18)*G17) -> 0.70699632 | F17: =+"L(t;"&D18&","&D17&")" -> L(t;7.25,7.5) | G17: 0.05 | H17: =+G17+G17*Volatility!G17*(-DriftSum!H17*TimeStep+SQRT(TimeStep)*H$49) -> 0.051249896 | I17: =+H17+H17*Volatility!H17*(-DriftSum!I17*TimeStep+SQRT(TimeStep)*I$49) -> 0.051331608 | J17: =+I17+I17*Volatility!I17*(-DriftSum!J17*TimeStep+SQRT(TimeStep)*J$49) -> 0.050117155 | K17: =+J17+J17*Volatility!J17*(-DriftSum!K17*TimeStep+SQRT(TimeStep)*K$49) -> 0.050535643 | L17: =+K17+K17*Volatility!K17*(-DriftSum!L17*TimeStep+SQRT(TimeStep)*L$49) -> 0.04917613 | M17: =+L17+L17*Volatility!L17*(-DriftSum!M17*TimeStep+SQRT(TimeStep)*M$49) -> 0.052029342 | N17: =+M17+M17*Volatility!M17*(-DriftSum!N17*TimeStep+SQRT(TimeStep)*N$49) -> 0.05159032 | O17: =+N17+N17*Volatility!N17*(-DriftSum!O17*TimeStep+SQRT(TimeStep)*O$49) -> 0.053252751 | ... CJ17: =+CI17+CI17*Volatility!CI17*(-DriftSum!CJ17*TimeStep+SQRT(TimeStep)*CJ$49) -> 0.053258333 | CK17: =+CJ17-CJ17*Volatility!CJ17*DriftSum!CK17*TimeStep+Volatility!CJ17*CJ17*SQRT(TimeStep)*CK$49 -> 0.052673988 | CL17: =+CK17-CK17*Volatility!CK17*DriftSum!CL17*TimeStep+Volatility!CK17*CK17*SQRT(TimeStep)*CL$49 -> 0.054024926 | CM17: =+CL17-CL17*Volatility!CL17*DriftSum!CM17*TimeStep+Volatility!CL17*CL17*SQRT(TimeStep)*CM$49 -> 0.053269449 | CN17: =+CM17-CM17*Volatility!CM17*DriftSum!CN17*TimeStep+Volatility!CM17*CM17*SQRT(TimeStep)*CN$49 -> 0.05237227 | CO17: =+CN17-CN17*Volatility!CN17*DriftSum!CO17*TimeStep+Volatility!CN17*CN17*SQRT(TimeStep)*CO$49 -> 0.049717411 | CP17: =+CO17-CO17*Volatility!CO17*DriftSum!CP17*TimeStep+Volatility!CO17*CO17*SQRT(TimeStep)*CP$49 -> 0.050648989
D18: =+D19+$E$3 -> 7.25 | E18: =+E19/(1+(D18-D19)*G18) -> 0.71583378 | F18: =+"L(t;"&D19&","&D18&")" -> L(t;7,7.25) | G18: 0.05 | H18: =+G18+G18*Volatility!G18*(-DriftSum!H18*TimeStep+SQRT(TimeStep)*H$49) -> 0.051287252 | I18: =+H18+H18*Volatility!H18*(-DriftSum!I18*TimeStep+SQRT(TimeStep)*I$49) -> 0.05137092 | J18: =+I18+I18*Volatility!I18*(-DriftSum!J18*TimeStep+SQRT(TimeStep)*J$49) -> 0.050118867 | K18: =+J18+J18*Volatility!J18*(-DriftSum!K18*TimeStep+SQRT(TimeStep)*K$49) -> 0.050549257 | L18: =+K18+K18*Volatility!K18*(-DriftSum!L18*TimeStep+SQRT(TimeStep)*L$49) -> 0.049148433 | M18: =+L18+L18*Volatility!L18*(-DriftSum!M18*TimeStep+SQRT(TimeStep)*M$49) -> 0.052084217 | N18: =+M18+M18*Volatility!M18*(-DriftSum!N18*TimeStep+SQRT(TimeStep)*N$49) -> 0.051631093 | O18: =+N18+N18*Volatility!N18*(-DriftSum!O18*TimeStep+SQRT(TimeStep)*O$49) -> 0.053343679 | ... CJ18: =+CI18+CI18*Volatility!CI18*(-DriftSum!CJ18*TimeStep+SQRT(TimeStep)*CJ$49) -> 0.053243367 | CK18: =+CJ18-CJ18*Volatility!CJ18*DriftSum!CK18*TimeStep+Volatility!CJ18*CJ18*SQRT(TimeStep)*CK$49 -> 0.052641222 | CL18: =+CK18-CK18*Volatility!CK18*DriftSum!CL18*TimeStep+Volatility!CK18*CK18*SQRT(TimeStep)*CL$49 -> 0.054030822 | CM18: =+CL18-CL18*Volatility!CL18*DriftSum!CM18*TimeStep+Volatility!CL18*CL18*SQRT(TimeStep)*CM$49 -> 0.05325219
D19: =+D20+$E$3 -> 7 | E19: =+E20/(1+(D19-D20)*G19) -> 0.7247817 | F19: =+"L(t;"&D20&","&D19&")" -> L(t;6.75,7) | G19: 0.05 | H19: =+G19+G19*Volatility!G19*(-DriftSum!H19*TimeStep+SQRT(TimeStep)*H$49) -> 0.051324562 | I19: =+H19+H19*Volatility!H19*(-DriftSum!I19*TimeStep+SQRT(TimeStep)*I$49) -> 0.051410138 | J19: =+I19+I19*Volatility!I19*(-DriftSum!J19*TimeStep+SQRT(TimeStep)*J$49) -> 0.05012038 | K19: =+J19+J19*Volatility!J19*(-DriftSum!K19*TimeStep+SQRT(TimeStep)*K$49) -> 0.050562623 | L19: =+K19+K19*Volatility!K19*(-DriftSum!L19*TimeStep+SQRT(TimeStep)*L$49) -> 0.049120425 | M19: =+L19+L19*Volatility!L19*(-DriftSum!M19*TimeStep+SQRT(TimeStep)*M$49) -> 0.05213862 | N19: =+M19+M19*Volatility!M19*(-DriftSum!N19*TimeStep+SQRT(TimeStep)*N$49) -> 0.051671317 | O19: =+N19+N19*Volatility!N19*(-DriftSum!O19*TimeStep+SQRT(TimeStep)*O$49) -> 0.053434067 | ... CJ19: =+CI19+CI19*Volatility!CI19*(-DriftSum!CJ19*TimeStep+SQRT(TimeStep)*CJ$49) -> 0.05322001
D20: =+D21+$E$3 -> 6.75 | E20: =+E21/(1+(D20-D21)*G20) -> 0.73384147 | F20: =+"L(t;"&D21&","&D20&")" -> L(t;6.5,6.75) | G20: 0.05 | H20: =+G20+G20*Volatility!G20*(-DriftSum!H20*TimeStep+SQRT(TimeStep)*H$49) -> 0.051361823 | I20: =+H20+H20*Volatility!H20*(-DriftSum!I20*TimeStep+SQRT(TimeStep)*I$49) -> 0.051449259 | J20: =+I20+I20*Volatility!I20*(-DriftSum!J20*TimeStep+SQRT(TimeStep)*J$49) -> 0.05012169 | K20: =+J20+J20*Volatility!J20*(-DriftSum!K20*TimeStep+SQRT(TimeStep)*K$49) -> 0.050575736 | L20: =+K20+K20*Volatility!K20*(-DriftSum!L20*TimeStep+SQRT(TimeStep)*L$49) -> 0.049092098 | M20: =+L20+L20*Volatility!L20*(-DriftSum!M20*TimeStep+SQRT(TimeStep)*M$49) -> 0.052192543 | N20: =+M20+M20*Volatility!M20*(-DriftSum!N20*TimeStep+SQRT(TimeStep)*N$49) -> 0.051710982 | O20: =+N20+N20*Volatility!N20*(-DriftSum!O20*TimeStep+SQRT(TimeStep)*O$49) -> 0.053523899 | ... CG20: =+CF20+CF20*Volatility!CF20*(-DriftSum!CG20*TimeStep+SQRT(TimeStep)*CG$49) -> 0.056782317
D21: =+D22+$E$3 -> 6.5 | E21: =+E22/(1+(D21-D22)*G21) -> 0.74301449 | F21: =+"L(t;"&D22&","&D21&")" -> L(t;6.25,6.5) | G21: 0.05 | H21: =+G21+G21*Volatility!G21*(-DriftSum!H21*TimeStep+SQRT(TimeStep)*H$49) -> 0.051399035 | I21: =+H21+H21*Volatility!H21*(-DriftSum!I21*TimeStep+SQRT(TimeStep)*I$49) -> 0.051488279 | J21: =+I21+I21*Volatility!I21*(-DriftSum!J21*TimeStep+SQRT(TimeStep)*J$49) -> 0.050122792 | K21: =+J21+J21*Volatility!J21*(-DriftSum!K21*TimeStep+SQRT(TimeStep)*K$49) -> 0.050588589 | L21: =+K21+K21*Volatility!K21*(-DriftSum!L21*TimeStep+SQRT(TimeStep)*L$49) -> 0.049063447 | M21: =+L21+L21*Volatility!L21*(-DriftSum!M21*TimeStep+SQRT(TimeStep)*M$49) -> 0.052245974 | N21: =+M21+M21*Volatility!M21*(-DriftSum!N21*TimeStep+SQRT(TimeStep)*N$49) -> 0.051750076 | O21: =+N21+N21*Volatility!N21*(-DriftSum!O21*TimeStep+SQRT(TimeStep)*O$49) -> 0.053613161 | ... CD21: =+CC21+CC21*Volatility!CC21*(-DriftSum!CD21*TimeStep+SQRT(TimeStep)*CD$49) -> 0.056339516
D22: =+D23+$E$3 -> 6.25 | E22: =+E23/(1+(D22-D23)*G22) -> 0.75230217 | F22: =+"L(t;"&D23&","&D22&")" -> L(t;6,6.25) | G22: 0.05 | H22: =+G22+G22*Volatility!G22*(-DriftSum!H22*TimeStep+SQRT(TimeStep)*H$49) -> 0.051436196 | I22: =+H22+H22*Volatility!H22*(-DriftSum!I22*TimeStep+SQRT(TimeStep)*I$49) -> 0.051527196 | J22: =+I22+I22*Volatility!I22*(-DriftSum!J22*TimeStep+SQRT(TimeStep)*J$49) -> 0.050123682 | K22: =+J22+J22*Volatility!J22*(-DriftSum!K22*TimeStep+SQRT(TimeStep)*K$49) -> 0.050601177 | L22: =+K22+K22*Volatility!K22*(-DriftSum!L22*TimeStep+SQRT(TimeStep)*L$49) -> 0.049034465 | M22: =+L22+L22*Volatility!L22*(-DriftSum!M22*TimeStep+SQRT(TimeStep)*M$49) -> 0.052298904 | N22: =+M22+M22*Volatility!M22*(-DriftSum!N22*TimeStep+SQRT(TimeStep)*N$49) -> 0.051788589 | O22: =+N22+N22*Volatility!N22*(-DriftSum!O22*TimeStep+SQRT(TimeStep)*O$49) -> 0.053701837 | ... CA22: =+BZ22+BZ22*Volatility!BZ22*(-DriftSum!CA22*TimeStep+SQRT(TimeStep)*CA$49) -> 0.054338475
D23: =+D24+$E$3 -> 6 | E23: =+E24/(1+(D23-D24)*G23) -> 0.76170595 | F23: =+"L(t;"&D24&","&D23&")" -> L(t;5.75,6) | G23: 0.0496875 | H23: =+G23+G23*Volatility!G23*(-DriftSum!H23*TimeStep+SQRT(TimeStep)*H$49) -> 0.051151596 | I23: =+H23+H23*Volatility!H23*(-DriftSum!I23*TimeStep+SQRT(TimeStep)*I$49) -> 0.051243719 | J23: =+I23+I23*Volatility!I23*(-DriftSum!J23*TimeStep+SQRT(TimeStep)*J$49) -> 0.049811079 | K23: =+J23+J23*Volatility!J23*(-DriftSum!K23*TimeStep+SQRT(TimeStep)*K$49) -> 0.050297159 | L23: =+K23+K23*Volatility!K23*(-DriftSum!L23*TimeStep+SQRT(TimeStep)*L$49) -> 0.048698862 | M23: =+L23+L23*Volatility!L23*(-DriftSum!M23*TimeStep+SQRT(TimeStep)*M$49) -> 0.052024128 | N23: =+M23+M23*Volatility!M23*(-DriftSum!N23*TimeStep+SQRT(TimeStep)*N$49) -> 0.051502593 | O23: =+N23+N23*Volatility!N23*(-DriftSum!O23*TimeStep+SQRT(TimeStep)*O$49) -> 0.053453725 | ... BX23: =+BW23+BW23*Volatility!BW23*(-DriftSum!BX23*TimeStep+SQRT(TimeStep)*BX$49) -> 0.051670359
D24: =+D25+$E$3 -> 5.75 | E24: =+E25/(1+(D24-D25)*G24) -> 0.77116776 | F24: =+"L(t;"&D25&","&D24&")" -> L(t;5.5,5.75) | G24: 0.049375 | H24: =+G24+G24*Volatility!G24*(-DriftSum!H24*TimeStep+SQRT(TimeStep)*H$49) -> 0.050866484 | I24: =+H24+H24*Volatility!H24*(-DriftSum!I24*TimeStep+SQRT(TimeStep)*I$49) -> 0.050959659 | J24: =+I24+I24*Volatility!I24*(-DriftSum!J24*TimeStep+SQRT(TimeStep)*J$49) -> 0.049498264 | K24: =+J24+J24*Volatility!J24*(-DriftSum!K24*TimeStep+SQRT(TimeStep)*K$49) -> 0.049992731 | L24: =+K24+K24*Volatility!K24*(-DriftSum!L24*TimeStep+SQRT(TimeStep)*L$49) -> 0.048363307 | M24: =+L24+L24*Volatility!L24*(-DriftSum!M24*TimeStep+SQRT(TimeStep)*M$49) -> 0.05174821 | N24: =+M24+M24*Volatility!M24*(-DriftSum!N24*TimeStep+SQRT(TimeStep)*N$49) -> 0.051215559 | O24: =+N24+N24*Volatility!N24*(-DriftSum!O24*TimeStep+SQRT(TimeStep)*O$49) -> 0.053203943 | ... BU24: =+BT24+BT24*Volatility!BT24*(-DriftSum!BU24*TimeStep+SQRT(TimeStep)*BU$49) -> 0.053759623
D25: =+D26+$E$3 -> 5.5 | E25: =+E26/(1+(D25-D26)*G25) -> 0.78068687 | F25: =+"L(t;"&D26&","&D25&")" -> L(t;5.25,5.5) | G25: 0.0490625 | H25: =+G25+G25*Volatility!G25*(-DriftSum!H25*TimeStep+SQRT(TimeStep)*H$49) -> 0.050580859 | I25: =+H25+H25*Volatility!H25*(-DriftSum!I25*TimeStep+SQRT(TimeStep)*I$49) -> 0.050675014 | J25: =+I25+I25*Volatility!I25*(-DriftSum!J25*TimeStep+SQRT(TimeStep)*J$49) -> 0.049185236 | K25: =+J25+J25*Volatility!J25*(-DriftSum!K25*TimeStep+SQRT(TimeStep)*K$49) -> 0.049687895 | L25: =+K25+K25*Volatility!K25*(-DriftSum!L25*TimeStep+SQRT(TimeStep)*L$49) -> 0.048027804 | M25: =+L25+L25*Volatility!L25*(-DriftSum!M25*TimeStep+SQRT(TimeStep)*M$49) -> 0.051471154 | N25: =+M25+M25*Volatility!M25*(-DriftSum!N25*TimeStep+SQRT(TimeStep)*N$49) -> 0.050927491 | O25: =+N25+N25*Volatility!N25*(-DriftSum!O25*TimeStep+SQRT(TimeStep)*O$49) -> 0.052952493 | ... BR25: =+BQ25+BQ25*Volatility!BQ25*(-DriftSum!BR25*TimeStep+SQRT(TimeStep)*BR$49) -> 0.062595696
D26: =+D27+$E$3 -> 5.25 | E26: =+E27/(1+(D26-D27)*G26) -> 0.79026248 | F26: =+"L(t;"&D27&","&D26&")" -> L(t;5,5.25) | G26: 0.04875 | H26: =+G26+G26*Volatility!G26*(-DriftSum!H26*TimeStep+SQRT(TimeStep)*H$49) -> 0.050294723 | I26: =+H26+H26*Volatility!H26*(-DriftSum!I26*TimeStep+SQRT(TimeStep)*I$49) -> 0.050389785 | J26: =+I26+I26*Volatility!I26*(-DriftSum!J26*TimeStep+SQRT(TimeStep)*J$49) -> 0.048871999 | K26: =+J26+J26*Volatility!J26*(-DriftSum!K26*TimeStep+SQRT(TimeStep)*K$49) -> 0.049382652 | L26: =+K26+K26*Volatility!K26*(-DriftSum!L26*TimeStep+SQRT(TimeStep)*L$49) -> 0.047692354 | M26: =+L26+L26*Volatility!L26*(-DriftSum!M26*TimeStep+SQRT(TimeStep)*M$49) -> 0.051192963 | N26: =+M26+M26*Volatility!M26*(-DriftSum!N26*TimeStep+SQRT(TimeStep)*N$49) -> 0.050638394 | O26: =+N26+N26*Volatility!N26*(-DriftSum!O26*TimeStep+SQRT(TimeStep)*O$49) -> 0.052699376 | ... BO26: =+BN26+BN26*Volatility!BN26*(-DriftSum!BO26*TimeStep+SQRT(TimeStep)*BO$49) -> 0.058841195
D27: =+D28+$E$3 -> 5 | E27: =+E28/(1+(D27-D28)*G27) -> 0.7998938 | F27: =+"L(t;"&D28&","&D27&")" -> L(t;4.75,5) | G27: 0.0484375 | H27: =+G27+G27*Volatility!G27*(-DriftSum!H27*TimeStep+SQRT(TimeStep)*H$49) -> 0.050008074 | I27: =+H27+H27*Volatility!H27*(-DriftSum!I27*TimeStep+SQRT(TimeStep)*I$49) -> 0.050103973 | J27: =+I27+I27*Volatility!I27*(-DriftSum!J27*TimeStep+SQRT(TimeStep)*J$49) -> 0.048558554 | K27: =+J27+J27*Volatility!J27*(-DriftSum!K27*TimeStep+SQRT(TimeStep)*K$49) -> 0.049077004 | L27: =+K27+K27*Volatility!K27*(-DriftSum!L27*TimeStep+SQRT(TimeStep)*L$49) -> 0.04735696 | M27: =+L27+L27*Volatility!L27*(-DriftSum!M27*TimeStep+SQRT(TimeStep)*M$49) -> 0.05091364 | N27: =+M27+M27*Volatility!M27*(-DriftSum!N27*TimeStep+SQRT(TimeStep)*N$49) -> 0.050348271 | O27: =+N27+N27*Volatility!N27*(-DriftSum!O27*TimeStep+SQRT(TimeStep)*O$49) -> 0.052444594 | ... BL27: =+BK27+BK27*Volatility!BK27*(-DriftSum!BL27*TimeStep+SQRT(TimeStep)*BL$49) -> 0.058296583
D28: =+D29+$E$3 -> 4.75 | E28: =+E29/(1+(D28-D29)*G28) -> 0.80958002 | F28: =+"L(t;"&D29&","&D28&")" -> L(t;4.5,4.75) | G28: 0.048125 | H28: =+G28+G28*Volatility!G28*(-DriftSum!H28*TimeStep+SQRT(TimeStep)*H$49) -> 0.049720913 | I28: =+H28+H28*Volatility!H28*(-DriftSum!I28*TimeStep+SQRT(TimeStep)*I$49) -> 0.049817578 | J28: =+I28+I28*Volatility!I28*(-DriftSum!J28*TimeStep+SQRT(TimeStep)*J$49) -> 0.048244902 | K28: =+J28+J28*Volatility!J28*(-DriftSum!K28*TimeStep+SQRT(TimeStep)*K$49) -> 0.048770953 | L28: =+K28+K28*Volatility!K28*(-DriftSum!L28*TimeStep+SQRT(TimeStep)*L$49) -> 0.047021626 | M28: =+L28+L28*Volatility!L28*(-DriftSum!M28*TimeStep+SQRT(TimeStep)*M$49) -> 0.05063319 | N28: =+M28+M28*Volatility!M28*(-DriftSum!N28*TimeStep+SQRT(TimeStep)*N$49) -> 0.050057129 | O28: =+N28+N28*Volatility!N28*(-DriftSum!O28*TimeStep+SQRT(TimeStep)*O$49) -> 0.052188148 | ... BI28: =+BH28+BH28*Volatility!BH28*(-DriftSum!BI28*TimeStep+SQRT(TimeStep)*BI$49) -> 0.053480816
D29: =+D30+$E$3 -> 4.5 | E29: =+E30/(1+(D29-D30)*G29) -> 0.81932028 | F29: =+"L(t;"&D30&","&D29&")" -> L(t;4.25,4.5) | G29: 0.0478125 | H29: =+G29+G29*Volatility!G29*(-DriftSum!H29*TimeStep+SQRT(TimeStep)*H$49) -> 0.049433242 | I29: =+H29+H29*Volatility!H29*(-DriftSum!I29*TimeStep+SQRT(TimeStep)*I$49) -> 0.0495306 | J29: =+I29+I29*Volatility!I29*(-DriftSum!J29*TimeStep+SQRT(TimeStep)*J$49) -> 0.047931044 | K29: =+J29+J29*Volatility!J29*(-DriftSum!K29*TimeStep+SQRT(TimeStep)*K$49) -> 0.0484645 | L29: =+K29+K29*Volatility!K29*(-DriftSum!L29*TimeStep+SQRT(TimeStep)*L$49) -> 0.046686354 | M29: =+L29+L29*Volatility!L29*(-DriftSum!M29*TimeStep+SQRT(TimeStep)*M$49) -> 0.050351617 | N29: =+M29+M29*Volatility!M29*(-DriftSum!N29*TimeStep+SQRT(TimeStep)*N$49) -> 0.049764971 | O29: =+N29+N29*Volatility!N29*(-DriftSum!O29*TimeStep+SQRT(TimeStep)*O$49) -> 0.051930043 | ... BF29: =+BE29+BE29*Volatility!BE29*(-DriftSum!BF29*TimeStep+SQRT(TimeStep)*BF$49) -> 0.056438927
D30: =+D31+$E$3 -> 4.25 | E30: =+E31/(1+(D30-D31)*G30) -> 0.82911371 | F30: =+"L(t;"&D31&","&D30&")" -> L(t;4,4.25) | G30: 0.0475 | H30: =+G30+G30*Volatility!G30*(-DriftSum!H30*TimeStep+SQRT(TimeStep)*H$49) -> 0.049145058 | I30: =+H30+H30*Volatility!H30*(-DriftSum!I30*TimeStep+SQRT(TimeStep)*I$49) -> 0.049243039 | J30: =+I30+I30*Volatility!I30*(-DriftSum!J30*TimeStep+SQRT(TimeStep)*J$49) -> 0.047616984 | K30: =+J30+J30*Volatility!J30*(-DriftSum!K30*TimeStep+SQRT(TimeStep)*K$49) -> 0.048157648 | L30: =+K30+K30*Volatility!K30*(-DriftSum!L30*TimeStep+SQRT(TimeStep)*L$49) -> 0.046351149 | M30: =+L30+L30*Volatility!L30*(-DriftSum!M30*TimeStep+SQRT(TimeStep)*M$49) -> 0.050068925 | N30: =+M30+M30*Volatility!M30*(-DriftSum!N30*TimeStep+SQRT(TimeStep)*N$49) -> 0.049471803 | O30: =+N30+N30*Volatility!N30*(-DriftSum!O30*TimeStep+SQRT(TimeStep)*O$49) -> 0.05167028 | ... BC30: =+BB30+BB30*Volatility!BB30*(-DriftSum!BC30*TimeStep+SQRT(TimeStep)*BC$49) -> 0.061707678
D31: =+D32+$E$3 -> 4 | E31: =+E32/(1+(D31-D32)*G31) -> 0.83895944 | F31: =+"L(t;"&D32&","&D31&")" -> L(t;3.75,4) | G31: 0.0471875 | H31: =+G31+G31*Volatility!G31*(-DriftSum!H31*TimeStep+SQRT(TimeStep)*H$49) -> 0.048856365 | I31: =+H31+H31*Volatility!H31*(-DriftSum!I31*TimeStep+SQRT(TimeStep)*I$49) -> 0.048954897 | J31: =+I31+I31*Volatility!I31*(-DriftSum!J31*TimeStep+SQRT(TimeStep)*J$49) -> 0.047302723 | K31: =+J31+J31*Volatility!J31*(-DriftSum!K31*TimeStep+SQRT(TimeStep)*K$49) -> 0.0478504 | L31: =+K31+K31*Volatility!K31*(-DriftSum!L31*TimeStep+SQRT(TimeStep)*L$49) -> 0.046016012 | M31: =+L31+L31*Volatility!L31*(-DriftSum!M31*TimeStep+SQRT(TimeStep)*M$49) -> 0.049785119 | N31: =+M31+M31*Volatility!M31*(-DriftSum!N31*TimeStep+SQRT(TimeStep)*N$49) -> 0.049177632 | O31: =+N31+N31*Volatility!N31*(-DriftSum!O31*TimeStep+SQRT(TimeStep)*O$49) -> 0.051408864 | ... AZ31: =+AY31+AY31*Volatility!AY31*(-DriftSum!AZ31*TimeStep+SQRT(TimeStep)*AZ$49) -> 0.059219806
D32: =+D33+$E$3 -> 3.75 | E32: =+E33/(1+(D32-D33)*G32) -> 0.84885654 | F32: =+"L(t;"&D33&","&D32&")" -> L(t;3.5,3.75) | G32: 0.046875 | H32: =+G32+G32*Volatility!G32*(-DriftSum!H32*TimeStep+SQRT(TimeStep)*H$49) -> 0.04856716 | I32: =+H32+H32*Volatility!H32*(-DriftSum!I32*TimeStep+SQRT(TimeStep)*I$49) -> 0.048666173 | J32: =+I32+I32*Volatility!I32*(-DriftSum!J32*TimeStep+SQRT(TimeStep)*J$49) -> 0.046988263 | K32: =+J32+J32*Volatility!J32*(-DriftSum!K32*TimeStep+SQRT(TimeStep)*K$49) -> 0.047542757 | L32: =+K32+K32*Volatility!K32*(-DriftSum!L32*TimeStep+SQRT(TimeStep)*L$49) -> 0.045680949 | M32: =+L32+L32*Volatility!L32*(-DriftSum!M32*TimeStep+SQRT(TimeStep)*M$49) -> 0.049500204 | N32: =+M32+M32*Volatility!M32*(-DriftSum!N32*TimeStep+SQRT(TimeStep)*N$49) -> 0.048882463 | O32: =+N32+N32*Volatility!N32*(-DriftSum!O32*TimeStep+SQRT(TimeStep)*O$49) -> 0.051145798 | ... AW32: =+AV32+AV32*Volatility!AV32*(-DriftSum!AW32*TimeStep+SQRT(TimeStep)*AW$49) -> 0.058277735
D33: =+D34+$E$3 -> 3.5 | E33: =+E34/(1+(D33-D34)*G33) -> 0.85880408 | F33: =+"L(t;"&D34&","&D33&")" -> L(t;3.25,3.5) | G33: 0.0465625 | H33: =+G33+G33*Volatility!G33*(-DriftSum!H33*TimeStep+SQRT(TimeStep)*H$49) -> 0.048277446 | I33: =+H33+H33*Volatility!H33*(-DriftSum!I33*TimeStep+SQRT(TimeStep)*I$49) -> 0.048376869 | J33: =+I33+I33*Volatility!I33*(-DriftSum!J33*TimeStep+SQRT(TimeStep)*J$49) -> 0.046673607 | K33: =+J33+J33*Volatility!J33*(-DriftSum!K33*TimeStep+SQRT(TimeStep)*K$49) -> 0.047234722 | L33: =+K33+K33*Volatility!K33*(-DriftSum!L33*TimeStep+SQRT(TimeStep)*L$49) -> 0.045345963 | M33: =+L33+L33*Volatility!L33*(-DriftSum!M33*TimeStep+SQRT(TimeStep)*M$49) -> 0.049214185 | N33: =+M33+M33*Volatility!M33*(-DriftSum!N33*TimeStep+SQRT(TimeStep)*N$49) -> 0.048586303 | O33: =+N33+N33*Volatility!N33*(-DriftSum!O33*TimeStep+SQRT(TimeStep)*O$49) -> 0.050881087 | ... AT33: =+AS33+AS33*Volatility!AS33*(-DriftSum!AT33*TimeStep+SQRT(TimeStep)*AT$49) -> 0.053274824
D34: =+D35+$E$3 -> 3.25 | E34: =+E35/(1+(D34-D35)*G34) -> 0.86880109 | F34: =+"L(t;"&D35&","&D34&")" -> L(t;3,3.25) | G34: 0.04625 | H34: =+G34+G34*Volatility!G34*(-DriftSum!H34*TimeStep+SQRT(TimeStep)*H$49) -> 0.047987223 | I34: =+H34+H34*Volatility!H34*(-DriftSum!I34*TimeStep+SQRT(TimeStep)*I$49) -> 0.048086324 | J34: =+I34+I34*Volatility!I34*(-DriftSum!J34*TimeStep+SQRT(TimeStep)*J$49) -> 0.046380859 | K34: =+J34+J34*Volatility!J34*(-DriftSum!K34*TimeStep+SQRT(TimeStep)*K$49) -> 0.046941201 | L34: =+K34+K34*Volatility!K34*(-DriftSum!L34*TimeStep+SQRT(TimeStep)*L$49) -> 0.045050561 | M34: =+L34+L34*Volatility!L34*(-DriftSum!M34*TimeStep+SQRT(TimeStep)*M$49) -> 0.048918435 | N34: =+M34+M34*Volatility!M34*(-DriftSum!N34*TimeStep+SQRT(TimeStep)*N$49) -> 0.04828903 | O34: =+N34+N34*Volatility!N34*(-DriftSum!O34*TimeStep+SQRT(TimeStep)*O$49) -> 0.050584002 | ... AQ34: =+AP34+AP34*Volatility!AP34*(-DriftSum!AQ34*TimeStep+SQRT(TimeStep)*AQ$49) -> 0.05314692
D35: =+D36+$E$3 -> 3 | E35: =+E36/(1+(D35-D36)*G35) -> 0.87884661 | F35: =+"L(t;"&D36&","&D35&")" -> L(t;2.75,3) | G35: 0.0459375 | H35: =+G35+G35*Volatility!G35*(-DriftSum!H35*TimeStep+SQRT(TimeStep)*H$49) -> 0.047662 | I35: =+H35+H35*Volatility!H35*(-DriftSum!I35*TimeStep+SQRT(TimeStep)*I$49) -> 0.047759371 | J35: =+I35+I35*Volatility!I35*(-DriftSum!J35*TimeStep+SQRT(TimeStep)*J$49) -> 0.046064438 | K35: =+J35+J35*Volatility!J35*(-DriftSum!K35*TimeStep+SQRT(TimeStep)*K$49) -> 0.046619967 | L35: =+K35+K35*Volatility!K35*(-DriftSum!L35*TimeStep+SQRT(TimeStep)*L$49) -> 0.044741251 | M35: =+L35+L35*Volatility!L35*(-DriftSum!M35*TimeStep+SQRT(TimeStep)*M$49) -> 0.048581634 | N35: =+M35+M35*Volatility!M35*(-DriftSum!N35*TimeStep+SQRT(TimeStep)*N$49) -> 0.047955463 | O35: =+N35+N35*Volatility!N35*(-DriftSum!O35*TimeStep+SQRT(TimeStep)*O$49) -> 0.050233509 | ... AN35: =+AM35+AM35*Volatility!AM35*(-DriftSum!AN35*TimeStep+SQRT(TimeStep)*AN$49) -> 0.055597134
D36: =+D37+$E$3 -> 2.75 | E36: =+E37/(1+(D36-D37)*G36) -> 0.88893961 | F36: =+"L(t;"&D37&","&D36&")" -> L(t;2.5,2.75) | G36: 0.045625 | H36: =+G36+G36*Volatility!G36*(-DriftSum!H36*TimeStep+SQRT(TimeStep)*H$49) -> 0.047336798 | I36: =+H36+H36*Volatility!H36*(-DriftSum!I36*TimeStep+SQRT(TimeStep)*I$49) -> 0.047432459 | J36: =+I36+I36*Volatility!I36*(-DriftSum!J36*TimeStep+SQRT(TimeStep)*J$49) -> 0.045748078 | K36: =+J36+J36*Volatility!J36*(-DriftSum!K36*TimeStep+SQRT(TimeStep)*K$49) -> 0.046298815 | L36: =+K36+K36*Volatility!K36*(-DriftSum!L36*TimeStep+SQRT(TimeStep)*L$49) -> 0.044432042 | M36: =+L36+L36*Volatility!L36*(-DriftSum!M36*TimeStep+SQRT(TimeStep)*M$49) -> 0.048244962 | N36: =+M36+M36*Volatility!M36*(-DriftSum!N36*TimeStep+SQRT(TimeStep)*N$49) -> 0.047622045 | O36: =+N36+N36*Volatility!N36*(-DriftSum!O36*TimeStep+SQRT(TimeStep)*O$49) -> 0.049883194 | ... AK36: =+AJ36+AJ36*Volatility!AJ36*(-DriftSum!AK36*TimeStep+SQRT(TimeStep)*AK$49) -> 0.059482291
D37: =+D38+$E$3 -> 2.5 | E37: =+E38/(1+(D37-D38)*G37) -> 0.89907908 | F37: =+"L(t;"&D38&","&D37&")" -> L(t;2.25,2.5) | G37: 0.0453125 | H37: =+G37+G37*Volatility!G37*(-DriftSum!H37*TimeStep+SQRT(TimeStep)*H$49) -> 0.047011615 | I37: =+H37+H37*Volatility!H37*(-DriftSum!I37*TimeStep+SQRT(TimeStep)*I$49) -> 0.047105588 | J37: =+I37+I37*Volatility!I37*(-DriftSum!J37*TimeStep+SQRT(TimeStep)*J$49) -> 0.04543178 | K37: =+J37+J37*Volatility!J37*(-DriftSum!K37*TimeStep+SQRT(TimeStep)*K$49) -> 0.045977746 | L37: =+K37+K37*Volatility!K37*(-DriftSum!L37*TimeStep+SQRT(TimeStep)*L$49) -> 0.044122931 | M37: =+L37+L37*Volatility!L37*(-DriftSum!M37*TimeStep+SQRT(TimeStep)*M$49) -> 0.047908417 | N37: =+M37+M37*Volatility!M37*(-DriftSum!N37*TimeStep+SQRT(TimeStep)*N$49) -> 0.047288774 | O37: =+N37+N37*Volatility!N37*(-DriftSum!O37*TimeStep+SQRT(TimeStep)*O$49) -> 0.049533056 | ... AH37: =+AG37+AG37*Volatility!AG37*(-DriftSum!AH37*TimeStep+SQRT(TimeStep)*AH$49) -> 0.051428813
D38: =+D39+$E$3 -> 2.25 | E38: =+E39/(1+(D38-D39)*G38) -> 0.90926396 | F38: =+"L(t;"&D39&","&D38&")" -> L(t;2,2.25) | G38: 0.045 | H38: =+G38+G38*Volatility!G38*(-DriftSum!H38*TimeStep+SQRT(TimeStep)*H$49) -> 0.046663966 | I38: =+H38+H38*Volatility!H38*(-DriftSum!I38*TimeStep+SQRT(TimeStep)*I$49) -> 0.046753767 | J38: =+I38+I38*Volatility!I38*(-DriftSum!J38*TimeStep+SQRT(TimeStep)*J$49) -> 0.045157933 | K38: =+J38+J38*Volatility!J38*(-DriftSum!K38*TimeStep+SQRT(TimeStep)*K$49) -> 0.045677989 | L38: =+K38+K38*Volatility!K38*(-DriftSum!L38*TimeStep+SQRT(TimeStep)*L$49) -> 0.043908041 | M38: =+L38+L38*Volatility!L38*(-DriftSum!M38*TimeStep+SQRT(TimeStep)*M$49) -> 0.047523546 | N38: =+M38+M38*Volatility!M38*(-DriftSum!N38*TimeStep+SQRT(TimeStep)*N$49) -> 0.046932455 | O38: =+N38+N38*Volatility!N38*(-DriftSum!O38*TimeStep+SQRT(TimeStep)*O$49) -> 0.049069745 | ... AE38: =+AD38+AD38*Volatility!AD38*(-DriftSum!AE38*TimeStep+SQRT(TimeStep)*AE$49) -> 0.048595626
D39: =+D40+$E$3 -> 2 | E39: =+E40/(1+(D39-D40)*G39) -> 0.91949318 | F39: =+"L(t;"&D40&","&D39&")" -> L(t;1.75,2) | G39: 0.044375 | H39: =+G39+G39*Volatility!G39*(-DriftSum!H39*TimeStep+SQRT(TimeStep)*H$49) -> 0.045948469 | I39: =+H39+H39*Volatility!H39*(-DriftSum!I39*TimeStep+SQRT(TimeStep)*I$49) -> 0.046032357 | J39: =+I39+I39*Volatility!I39*(-DriftSum!J39*TimeStep+SQRT(TimeStep)*J$49) -> 0.044525733 | K39: =+J39+J39*Volatility!J39*(-DriftSum!K39*TimeStep+SQRT(TimeStep)*K$49) -> 0.04501632 | L39: =+K39+K39*Volatility!K39*(-DriftSum!L39*TimeStep+SQRT(TimeStep)*L$49) -> 0.043343848 | M39: =+L39+L39*Volatility!L39*(-DriftSum!M39*TimeStep+SQRT(TimeStep)*M$49) -> 0.046763407 | N39: =+M39+M39*Volatility!M39*(-DriftSum!N39*TimeStep+SQRT(TimeStep)*N$49) -> 0.046205096 | O39: =+N39+N39*Volatility!N39*(-DriftSum!O39*TimeStep+SQRT(TimeStep)*O$49) -> 0.048220701 | ... AB39: =+AA39+AA39*Volatility!AA39*(-DriftSum!AB39*TimeStep+SQRT(TimeStep)*AB$49) -> 0.046610886
D40: =+D41+$E$3 -> 1.75 | E40: =+E41/(1+(D40-D41)*G40) -> 0.9296938 | F40: =+"L(t;"&D41&","&D40&")" -> L(t;1.5,1.75) | G40: 0.04375 | H40: =+G40+G40*Volatility!G40*(-DriftSum!H40*TimeStep+SQRT(TimeStep)*H$49) -> 0.045234987 | I40: =+H40+H40*Volatility!H40*(-DriftSum!I40*TimeStep+SQRT(TimeStep)*I$49) -> 0.04531323 | J40: =+I40+I40*Volatility!I40*(-DriftSum!J40*TimeStep+SQRT(TimeStep)*J$49) -> 0.043893842 | K40: =+J40+J40*Volatility!J40*(-DriftSum!K40*TimeStep+SQRT(TimeStep)*K$49) -> 0.044355706 | L40: =+K40+K40*Volatility!K40*(-DriftSum!L40*TimeStep+SQRT(TimeStep)*L$49) -> 0.042778678 | M40: =+L40+L40*Volatility!L40*(-DriftSum!M40*TimeStep+SQRT(TimeStep)*M$49) -> 0.046006213 | N40: =+M40+M40*Volatility!M40*(-DriftSum!N40*TimeStep+SQRT(TimeStep)*N$49) -> 0.045480017 | O40: =+N40+N40*Volatility!N40*(-DriftSum!O40*TimeStep+SQRT(TimeStep)*O$49) -> 0.047376944 | ... Y40: =+X40+X40*Volatility!X40*(-DriftSum!Y40*TimeStep+SQRT(TimeStep)*Y$49) -> 0.043654058
D41: =+D42+$E$3 -> 1.5 | E41: =+E42/(1+(D41-D42)*G41) -> 0.93986233 | F41: =+"L(t;"&D42&","&D41&")" -> L(t;1.25,1.5) | G41: 0.043125 | H41: =+G41+G41*Volatility!G41*(-DriftSum!H41*TimeStep+SQRT(TimeStep)*H$49) -> 0.044523507 | I41: =+H41+H41*Volatility!H41*(-DriftSum!I41*TimeStep+SQRT(TimeStep)*I$49) -> 0.04459636 | J41: =+I41+I41*Volatility!I41*(-DriftSum!J41*TimeStep+SQRT(TimeStep)*J$49) -> 0.043262232 | K41: =+J41+J41*Volatility!J41*(-DriftSum!K41*TimeStep+SQRT(TimeStep)*K$49) -> 0.043696107 | L41: =+K41+K41*Volatility!K41*(-DriftSum!L41*TimeStep+SQRT(TimeStep)*L$49) -> 0.042212483 | M41: =+L41+L41*Volatility!L41*(-DriftSum!M41*TimeStep+SQRT(TimeStep)*M$49) -> 0.045251917 | N41: =+M41+M41*Volatility!M41*(-DriftSum!N41*TimeStep+SQRT(TimeStep)*N$49) -> 0.044757161 | O41: =+N41+N41*Volatility!N41*(-DriftSum!O41*TimeStep+SQRT(TimeStep)*O$49) -> 0.046538387 | ... V41: =+U41+U41*Volatility!U41*(-DriftSum!V41*TimeStep+SQRT(TimeStep)*V$49) -> 0.046686777
...

Sheet Volatility
D2: Calculation of the Sum that appears in the drift part of Libor Market Model's SDE
G3: Initial
G4: Forward Libor
D6: Maturity (in years) | F6: =+F47 -> t (years) = | G6: =+G47 -> 0 | H6: =+H47 -> 0.083333333 | I6: =+I47 -> 0.16666667 | J6: =+J47 -> 0.25 | K6: =+K47 -> 0.33333333 | L6: =+L47 -> 0.41666667 | M6: =+M47 -> 0.5 | ... DW6: =+DW47 -> 10
D7: =+ForwardLiborSimulation!D7 -> 10 | F7: =+"L(t;"&D8&","&D7&")" -> L(t;9.75,10) | G7: 0.069 | H7: 0.07 | I7: 0.071 | J7: =+I7 -> 0.071 | K7: =+J7 -> 0.071 | L7: =+K7 -> 0.071 | M7: =+L7 -> 0.071 | N7: =+M7 -> 0.071 | O7: =+N7 -> 0.071 | P7: =+O7 -> 0.071 | Q7: =+P7 -> 0.071 | ... DS7: =+DR7 -> 0.071
D8: =+ForwardLiborSimulation!D8 -> 9.75 | F8: =+"L(t;"&D9&","&D8&")" -> L(t;9.5,9.75) | G8: 0.072 | H8: 0.073 | I8: 0.074 | J8: =+I8 -> 0.074 | K8: =+J8 -> 0.074 | L8: =+K8 -> 0.074 | M8: =+L8 -> 0.074 | N8: =+M8 -> 0.074 | O8: =+N8 -> 0.074 | P8: =+O8 -> 0.074 | Q8: =+P8 -> 0.074 | ... DP8: =+DO8 -> 0.074
D9: =+ForwardLiborSimulation!D9 -> 9.5 | F9: =+"L(t;"&D10&","&D9&")" -> L(t;9.25,9.5) | G9: 0.075 | H9: 0.076 | I9: 0.077 | J9: =+I9 -> 0.077 | K9: =+J9 -> 0.077 | L9: =+K9 -> 0.077 | M9: =+L9 -> 0.077 | N9: =+M9 -> 0.077 | O9: =+N9 -> 0.077 | P9: =+O9 -> 0.077 | Q9: =+P9 -> 0.077 | ... DM9: =+DL9 -> 0.077
D10: =+ForwardLiborSimulation!D10 -> 9.25 | F10: =+"L(t;"&D11&","&D10&")" -> L(t;9,9.25) | G10: 0.078 | H10: 0.079 | I10: 0.08 | J10: =+I10 -> 0.08 | K10: =+J10 -> 0.08 | L10: =+K10 -> 0.08 | M10: =+L10 -> 0.08 | N10: =+M10 -> 0.08 | O10: =+N10 -> 0.08 | P10: =+O10 -> 0.08 | Q10: =+P10 -> 0.08 | ... DJ10: =+DI10 -> 0.08
D11: =+ForwardLiborSimulation!D11 -> 9 | F11: =+"L(t;"&D12&","&D11&")" -> L(t;8.75,9) | G11: 0.081 | H11: 0.082 | I11: 0.083 | J11: =+I11 -> 0.083 | K11: =+J11 -> 0.083 | L11: =+K11 -> 0.083 | M11: =+L11 -> 0.083 | N11: =+M11 -> 0.083 | O11: =+N11 -> 0.083 | P11: =+O11 -> 0.083 | Q11: =+P11 -> 0.083 | ... DG11: =+DF11 -> 0.083
D12: =+ForwardLiborSimulation!D12 -> 8.75 | F12: =+"L(t;"&D13&","&D12&")" -> L(t;8.5,8.75) | G12: 0.084 | H12: 0.085 | I12: 0.086 | J12: =+I12 -> 0.086 | K12: =+J12 -> 0.086 | L12: =+K12 -> 0.086 | M12: =+L12 -> 0.086 | N12: =+M12 -> 0.086 | O12: =+N12 -> 0.086 | P12: =+O12 -> 0.086 | Q12: =+P12 -> 0.086 | ... DD12: =+DC12 -> 0.086
D13: =+ForwardLiborSimulation!D13 -> 8.5 | F13: =+"L(t;"&D14&","&D13&")" -> L(t;8.25,8.5) | G13: 0.087 | H13: 0.088 | I13: 0.089 | J13: =+I13 -> 0.089 | K13: =+J13 -> 0.089 | L13: =+K13 -> 0.089 | M13: =+L13 -> 0.089 | N13: =+M13 -> 0.089 | O13: =+N13 -> 0.089 | P13: =+O13 -> 0.089 | Q13: =+P13 -> 0.089 | ... DA13: =+CZ13 -> 0.089
D14: =+ForwardLiborSimulation!D14 -> 8.25 | F14: =+"L(t;"&D15&","&D14&")" -> L(t;8,8.25) | G14: 0.09 | H14: 0.091 | I14: 0.092 | J14: =+I14 -> 0.092 | K14: =+J14 -> 0.092 | L14: =+K14 -> 0.092 | M14: =+L14 -> 0.092 | N14: =+M14 -> 0.092 | O14: =+N14 -> 0.092 | P14: =+O14 -> 0.092 | Q14: =+P14 -> 0.092 | ... CX14: =+CW14 -> 0.092
D15: =+ForwardLiborSimulation!D15 -> 8 | F15: =+"L(t;"&D16&","&D15&")" -> L(t;7.75,8) | G15: 0.093 | H15: 0.094 | I15: 0.095 | J15: =+I15 -> 0.095 | K15: =+J15 -> 0.095 | L15: =+K15 -> 0.095 | M15: =+L15 -> 0.095 | N15: =+M15 -> 0.095 | O15: =+N15 -> 0.095 | P15: =+O15 -> 0.095 | Q15: =+P15 -> 0.095 | ... CU15: =+CT15 -> 0.095
D16: =+ForwardLiborSimulation!D16 -> 7.75 | F16: =+"L(t;"&D17&","&D16&")" -> L(t;7.5,7.75) | G16: 0.096 | H16: 0.097 | I16: 0.098 | J16: =+I16 -> 0.098 | K16: =+J16 -> 0.098 | L16: =+K16 -> 0.098 | M16: =+L16 -> 0.098 | N16: =+M16 -> 0.098 | O16: =+N16 -> 0.098 | P16: =+O16 -> 0.098 | Q16: =+P16 -> 0.098 | ... CR16: =+CQ16 -> 0.098
D17: =+ForwardLiborSimulation!D17 -> 7.5 | F17: =+"L(t;"&D18&","&D17&")" -> L(t;7.25,7.5) | G17: 0.099 | H17: 0.1 | I17: 0.101 | J17: =+I17 -> 0.101 | K17: =+J17 -> 0.101 | L17: =+K17 -> 0.101 | M17: =+L17 -> 0.101 | N17: =+M17 -> 0.101 | O17: =+N17 -> 0.101 | P17: =+O17 -> 0.101 | Q17: =+P17 -> 0.101 | ... CO17: =+CN17 -> 0.101
D18: =+ForwardLiborSimulation!D18 -> 7.25 | F18: =+"L(t;"&D19&","&D18&")" -> L(t;7,7.25) | G18: 0.102 | H18: 0.103 | I18: 0.104 | J18: =+I18 -> 0.104 | K18: =+J18 -> 0.104 | L18: =+K18 -> 0.104 | M18: =+L18 -> 0.104 | N18: =+M18 -> 0.104 | O18: =+N18 -> 0.104 | P18: =+O18 -> 0.104 | Q18: =+P18 -> 0.104 | ... CL18: =+CK18 -> 0.104
D19: =+ForwardLiborSimulation!D19 -> 7 | F19: =+"L(t;"&D20&","&D19&")" -> L(t;6.75,7) | G19: 0.105 | H19: 0.106 | I19: 0.107 | J19: =+I19 -> 0.107 | K19: =+J19 -> 0.107 | L19: =+K19 -> 0.107 | M19: =+L19 -> 0.107 | N19: =+M19 -> 0.107 | O19: =+N19 -> 0.107 | P19: =+O19 -> 0.107 | Q19: =+P19 -> 0.107 | ... CI19: =+CH19 -> 0.107
D20: =+ForwardLiborSimulation!D20 -> 6.75 | F20: =+"L(t;"&D21&","&D20&")" -> L(t;6.5,6.75) | G20: 0.108 | H20: 0.109 | I20: 0.11 | J20: =+I20 -> 0.11 | K20: =+J20 -> 0.11 | L20: =+K20 -> 0.11 | M20: =+L20 -> 0.11 | N20: =+M20 -> 0.11 | O20: =+N20 -> 0.11 | P20: =+O20 -> 0.11 | Q20: =+P20 -> 0.11 | ... CF20: =+CE20 -> 0.11
D21: =+ForwardLiborSimulation!D21 -> 6.5 | F21: =+"L(t;"&D22&","&D21&")" -> L(t;6.25,6.5) | G21: 0.111 | H21: 0.112 | I21: 0.113 | J21: =+I21 -> 0.113 | K21: =+J21 -> 0.113 | L21: =+K21 -> 0.113 | M21: =+L21 -> 0.113 | N21: =+M21 -> 0.113 | O21: =+N21 -> 0.113 | P21: =+O21 -> 0.113 | Q21: =+P21 -> 0.113 | ... CC21: =+CB21 -> 0.113
D22: =+ForwardLiborSimulation!D22 -> 6.25 | F22: =+"L(t;"&D23&","&D22&")" -> L(t;6,6.25) | G22: 0.114 | H22: 0.115 | I22: 0.116 | J22: =+I22 -> 0.116 | K22: =+J22 -> 0.116 | L22: =+K22 -> 0.116 | M22: =+L22 -> 0.116 | N22: =+M22 -> 0.116 | O22: =+N22 -> 0.116 | P22: =+O22 -> 0.116 | Q22: =+P22 -> 0.116 | ... BZ22: =+BY22 -> 0.116
D23: =+ForwardLiborSimulation!D23 -> 6 | F23: =+"L(t;"&D24&","&D23&")" -> L(t;5.75,6) | G23: 0.117 | H23: 0.118 | I23: 0.119 | J23: =+I23 -> 0.119 | K23: =+J23 -> 0.119 | L23: =+K23 -> 0.119 | M23: =+L23 -> 0.119 | N23: =+M23 -> 0.119 | O23: =+N23 -> 0.119 | P23: =+O23 -> 0.119 | Q23: =+P23 -> 0.119 | ... BW23: =+BV23 -> 0.119
D24: =+ForwardLiborSimulation!D24 -> 5.75 | F24: =+"L(t;"&D25&","&D24&")" -> L(t;5.5,5.75) | G24: 0.12 | H24: 0.121 | I24: 0.122 | J24: =+I24 -> 0.122 | K24: =+J24 -> 0.122 | L24: =+K24 -> 0.122 | M24: =+L24 -> 0.122 | N24: =+M24 -> 0.122 | O24: =+N24 -> 0.122 | P24: =+O24 -> 0.122 | Q24: =+P24 -> 0.122 | ... BT24: =+BS24 -> 0.122
D25: =+ForwardLiborSimulation!D25 -> 5.5 | F25: =+"L(t;"&D26&","&D25&")" -> L(t;5.25,5.5) | G25: 0.123 | H25: 0.124 | I25: 0.125 | J25: =+I25 -> 0.125 | K25: =+J25 -> 0.125 | L25: =+K25 -> 0.125 | M25: =+L25 -> 0.125 | N25: =+M25 -> 0.125 | O25: =+N25 -> 0.125 | P25: =+O25 -> 0.125 | Q25: =+P25 -> 0.125 | ... BQ25: =+BP25 -> 0.125
D26: =+ForwardLiborSimulation!D26 -> 5.25 | F26: =+"L(t;"&D27&","&D26&")" -> L(t;5,5.25) | G26: 0.126 | H26: 0.127 | I26: 0.128 | J26: =+I26 -> 0.128 | K26: =+J26 -> 0.128 | L26: =+K26 -> 0.128 | M26: =+L26 -> 0.128 | N26: =+M26 -> 0.128 | O26: =+N26 -> 0.128 | P26: =+O26 -> 0.128 | Q26: =+P26 -> 0.128 | ... BN26: =+BM26 -> 0.128
D27: =+ForwardLiborSimulation!D27 -> 5 | F27: =+"L(t;"&D28&","&D27&")" -> L(t;4.75,5) | G27: 0.129 | H27: 0.13 | I27: 0.131 | J27: =+I27 -> 0.131 | K27: =+J27 -> 0.131 | L27: =+K27 -> 0.131 | M27: =+L27 -> 0.131 | N27: =+M27 -> 0.131 | O27: =+N27 -> 0.131 | P27: =+O27 -> 0.131 | Q27: =+P27 -> 0.131 | ... BK27: =+BJ27 -> 0.131
D28: =+ForwardLiborSimulation!D28 -> 4.75 | F28: =+"L(t;"&D29&","&D28&")" -> L(t;4.5,4.75) | G28: 0.132 | H28: 0.133 | I28: 0.134 | J28: =+I28 -> 0.134 | K28: =+J28 -> 0.134 | L28: =+K28 -> 0.134 | M28: =+L28 -> 0.134 | N28: =+M28 -> 0.134 | O28: =+N28 -> 0.134 | P28: =+O28 -> 0.134 | Q28: =+P28 -> 0.134 | ... BH28: =+BG28 -> 0.134
D29: =+ForwardLiborSimulation!D29 -> 4.5 | F29: =+"L(t;"&D30&","&D29&")" -> L(t;4.25,4.5) | G29: 0.135 | H29: 0.136 | I29: 0.137 | J29: =+I29 -> 0.137 | K29: =+J29 -> 0.137 | L29: =+K29 -> 0.137 | M29: =+L29 -> 0.137 | N29: =+M29 -> 0.137 | O29: =+N29 -> 0.137 | P29: =+O29 -> 0.137 | Q29: =+P29 -> 0.137 | ... BE29: =+BD29 -> 0.137
D30: =+ForwardLiborSimulation!D30 -> 4.25 | F30: =+"L(t;"&D31&","&D30&")" -> L(t;4,4.25) | G30: 0.138 | H30: 0.139 | I30: 0.14 | J30: =+I30 -> 0.14 | K30: =+J30 -> 0.14 | L30: =+K30 -> 0.14 | M30: =+L30 -> 0.14 | N30: =+M30 -> 0.14 | O30: =+N30 -> 0.14 | P30: =+O30 -> 0.14 | Q30: =+P30 -> 0.14 | ... BB30: =+BA30 -> 0.14
D31: =+ForwardLiborSimulation!D31 -> 4 | F31: =+"L(t;"&D32&","&D31&")" -> L(t;3.75,4) | G31: 0.141 | H31: 0.142 | I31: 0.143 | J31: =+I31 -> 0.143 | K31: =+J31 -> 0.143 | L31: =+K31 -> 0.143 | M31: =+L31 -> 0.143 | N31: =+M31 -> 0.143 | O31: =+N31 -> 0.143 | P31: =+O31 -> 0.143 | Q31: =+P31 -> 0.143 | ... AY31: =+AX31 -> 0.143
D32: =+ForwardLiborSimulation!D32 -> 3.75 | F32: =+"L(t;"&D33&","&D32&")" -> L(t;3.5,3.75) | G32: 0.144 | H32: 0.145 | I32: 0.146 | J32: =+I32 -> 0.146 | K32: =+J32 -> 0.146 | L32: =+K32 -> 0.146 | M32: =+L32 -> 0.146 | N32: =+M32 -> 0.146 | O32: =+N32 -> 0.146 | P32: =+O32 -> 0.146 | Q32: =+P32 -> 0.146 | ... AV32: =+AU32 -> 0.146
D33: =+ForwardLiborSimulation!D33 -> 3.5 | F33: =+"L(t;"&D34&","&D33&")" -> L(t;3.25,3.5) | G33: 0.147 | H33: 0.148 | I33: 0.149 | J33: =+I33 -> 0.149 | K33: =+J33 -> 0.149 | L33: =+K33 -> 0.149 | M33: =+L33 -> 0.149 | N33: =+M33 -> 0.149 | O33: =+N33 -> 0.149 | P33: =+O33 -> 0.149 | Q33: =+P33 -> 0.149 | ... AS33: =+AR33 -> 0.149
D34: =+ForwardLiborSimulation!D34 -> 3.25 | F34: =+"L(t;"&D35&","&D34&")" -> L(t;3,3.25) | G34: 0.15 | H34: 0.15 | I34: 0.15 | J34: =+I34 -> 0.15 | K34: =+J34 -> 0.15 | L34: =+K34 -> 0.15 | M34: =+L34 -> 0.15 | N34: =+M34 -> 0.15 | O34: =+N34 -> 0.15 | P34: =+O34 -> 0.15 | Q34: =+P34 -> 0.15 | ... AP34: =+AO34 -> 0.15
D35: =+ForwardLiborSimulation!D35 -> 3 | F35: =+"L(t;"&D36&","&D35&")" -> L(t;2.75,3) | G35: 0.15 | H35: 0.15 | I35: 0.15 | J35: =+I35 -> 0.15 | K35: =+J35 -> 0.15 | L35: =+K35 -> 0.15 | M35: =+L35 -> 0.15 | N35: =+M35 -> 0.15 | O35: =+N35 -> 0.15 | P35: =+O35 -> 0.15 | Q35: =+P35 -> 0.15 | ... AM35: =+AL35 -> 0.15
D36: =+ForwardLiborSimulation!D36 -> 2.75 | F36: =+"L(t;"&D37&","&D36&")" -> L(t;2.5,2.75) | G36: 0.15 | H36: 0.15 | I36: 0.15 | J36: =+I36 -> 0.15 | K36: =+J36 -> 0.15 | L36: =+K36 -> 0.15 | M36: =+L36 -> 0.15 | N36: =+M36 -> 0.15 | O36: =+N36 -> 0.15 | P36: =+O36 -> 0.15 | Q36: =+P36 -> 0.15 | ... AJ36: =+AI36 -> 0.15
D37: =+ForwardLiborSimulation!D37 -> 2.5 | F37: =+"L(t;"&D38&","&D37&")" -> L(t;2.25,2.5) | G37: 0.15 | H37: 0.15 | I37: 0.15 | J37: =+I37 -> 0.15 | K37: =+J37 -> 0.15 | L37: =+K37 -> 0.15 | M37: =+L37 -> 0.15 | N37: =+M37 -> 0.15 | O37: =+N37 -> 0.15 | P37: =+O37 -> 0.15 | Q37: =+P37 -> 0.15 | ... AG37: =+AF37 -> 0.15
D38: =+ForwardLiborSimulation!D38 -> 2.25 | F38: =+"L(t;"&D39&","&D38&")" -> L(t;2,2.25) | G38: 0.148 | H38: 0.146 | I38: 0.144 | J38: =+I38 -> 0.144 | K38: =+J38 -> 0.144 | L38: =+K38 -> 0.144 | M38: =+L38 -> 0.144 | N38: =+M38 -> 0.144 | O38: =+N38 -> 0.144 | P38: =+O38 -> 0.144 | Q38: =+P38 -> 0.144 | ... AD38: =+AC38 -> 0.144
D39: =+ForwardLiborSimulation!D39 -> 2 | F39: =+"L(t;"&D40&","&D39&")" -> L(t;1.75,2) | G39: 0.142 | H39: 0.14 | I39: 0.138 | J39: =+I39 -> 0.138 | K39: =+J39 -> 0.138 | L39: =+K39 -> 0.138 | M39: =+L39 -> 0.138 | N39: =+M39 -> 0.138 | O39: =+N39 -> 0.138 | P39: =+O39 -> 0.138 | Q39: =+P39 -> 0.138 | ... AA39: =+Z39 -> 0.138
D40: =+ForwardLiborSimulation!D40 -> 1.75 | F40: =+"L(t;"&D41&","&D40&")" -> L(t;1.5,1.75) | G40: 0.136 | H40: 0.134 | I40: 0.132 | J40: =+I40 -> 0.132 | K40: =+J40 -> 0.132 | L40: =+K40 -> 0.132 | M40: =+L40 -> 0.132 | N40: =+M40 -> 0.132 | O40: =+N40 -> 0.132 | P40: =+O40 -> 0.132 | Q40: =+P40 -> 0.132 | ... X40: =+W40 -> 0.132
D41: =+ForwardLiborSimulation!D41 -> 1.5 | F41: =+"L(t;"&D42&","&D41&")" -> L(t;1.25,1.5) | G41: 0.13 | H41: 0.128 | I41: 0.126 | J41: =+I41 -> 0.126 | K41: =+J41 -> 0.126 | L41: =+K41 -> 0.126 | M41: =+L41 -> 0.126 | N41: =+M41 -> 0.126 | O41: =+N41 -> 0.126 | P41: =+O41 -> 0.126 | Q41: =+P41 -> 0.126 | ... U41: =+T41 -> 0.126
D42: =+ForwardLiborSimulation!D42 -> 1.25 | F42: =+"L(t;"&D43&","&D42&")" -> L(t;1,1.25) | G42: 0.124 | H42: 0.122 | I42: 0.12 | J42: =+I42 -> 0.12 | K42: =+J42 -> 0.12 | L42: =+K42 -> 0.12 | M42: =+L42 -> 0.12 | N42: =+M42 -> 0.12 | O42: =+N42 -> 0.12 | P42: =+O42 -> 0.12 | Q42: =+P42 -> 0.12 | R42: =+Q42 -> 0.12
...

Sheet DriftSum
D2: Calculation of the Summation Term that appears in the drift part of Libor Market Model's SDE
G3: Initial
G4: Forward Libor
D6: Maturity (in years) | F6: =+F47 -> t (years) = | G6: =+G47 -> 0 | H6: =+H47 -> 0.083333333 | I6: =+I47 -> 0.16666667 | J6: =+J47 -> 0.25 | K6: =+K47 -> 0.33333333 | L6: =+L47 -> 0.41666667 | M6: =+M47 -> 0.5 | ... DW6: =+DW47 -> 10
D7: =+ForwardLiborSimulation!D7 -> 10 | F7: =+"L(t;"&D8&","&D7&")" -> L(t;9.75,10) | H7: 0 | I7: 0 | J7: 0 | K7: 0 | L7: 0 | M7: 0 | N7: 0 | O7: 0 | P7: 0 | Q7: 0 | R7: 0 | S7: 0 | T7: 0 | U7: 0 | V7: 0 | W7: 0 | X7: 0 | Y7: 0 | Z7: 0 | AA7: 0 | AB7: 0 | AC7: 0 | AD7: 0 | AE7: 0 | AF7: 0 | AG7: 0 | AH7: 0 | AI7: 0 | AJ7: 0 | AK7: 0 | AL7: 0 | AM7: 0 | AN7: 0 | AO7: 0 | AP7: 0 | AQ7: 0 | AR7: 0 | AS7: 0 | AT7: 0 | AU7: 0 | AV7: 0 | AW7: 0 | AX7: 0 | AY7: 0 | AZ7: 0 | BA7: 0 | BB7: 0 | BC7: 0 | BD7: 0 | BE7: 0 | BF7: 0 | BG7: 0 | BH7: 0 | BI7: 0 | BJ7: 0 | BK7: 0 | BL7: 0 | BM7: 0 | BN7: 0 | BO7: 0 | BP7: 0 | BQ7: 0 | BR7: 0 | BS7: 0 | BT7: 0 | BU7: 0 | BV7: 0 | BW7: 0 | BX7: 0 | BY7: 0 | BZ7: 0 | CA7: 0 | CB7: 0 | CC7: 0 | CD7: 0 | CE7: 0 | CF7: 0 | CG7: 0 | CH7: 0 | CI7: 0 | CJ7: 0 | CK7: 0 | CL7: 0 | CM7: 0 | CN7: 0 | CO7: 0 | CP7: 0 | CQ7: 0 | CR7: 0 | CS7: 0 | CT7: 0 | CU7: 0 | CV7: 0 | CW7: 0 | CX7: 0 | CY7: 0 | CZ7: 0 | DA7: 0 | DB7: 0 | DC7: 0 | DD7: 0 | DE7: 0 | DF7: 0 | DG7: 0 | DH7: 0 | DI7: 0 | DJ7: 0 | DK7: 0 | DL7: 0 | DM7: 0 | DN7: 0 | DO7: 0 | DP7: 0 | DQ7: 0 | DR7: 0 | DS7: 0 | DT7: 0
D8: =+ForwardLiborSimulation!D8 -> 9.75 | F8: =+"L(t;"&D9&","&D8&")" -> L(t;9.5,9.75) | H8: =+H7+(LiborTenor*Volatility!G7*ForwardLiborSimulation!G7)/(1+LiborTenor*ForwardLiborSimulation!G7) -> 0.00085185185 | I8: =+I7+(LiborTenor*Volatility!H7*ForwardLiborSimulation!H7)/(1+LiborTenor*ForwardLiborSimulation!H7) -> 0.00087911515 | J8: =+J7+(LiborTenor*Volatility!I7*ForwardLiborSimulation!I7)/(1+LiborTenor*ForwardLiborSimulation!I7) -> 0.00089271064 | K8: =+K7+(LiborTenor*Volatility!J7*ForwardLiborSimulation!J7)/(1+LiborTenor*ForwardLiborSimulation!J7) -> 0.00087810273 | L8: =+L7+(LiborTenor*Volatility!K7*ForwardLiborSimulation!K7)/(1+LiborTenor*ForwardLiborSimulation!K7) -> 0.00088324665 | M8: =+M7+(LiborTenor*Volatility!L7*ForwardLiborSimulation!L7)/(1+LiborTenor*ForwardLiborSimulation!L7) -> 0.00086680153 | N8: =+N7+(LiborTenor*Volatility!M7*ForwardLiborSimulation!M7)/(1+LiborTenor*ForwardLiborSimulation!M7) -> 0.00090175843 | O8: =+O7+(LiborTenor*Volatility!N7*ForwardLiborSimulation!N7)/(1+LiborTenor*ForwardLiborSimulation!N7) -> 0.00089653391 | ... DQ8: =+DQ7+(LiborTenor*Volatility!DP7*ForwardLiborSimulation!DP7)/(1+LiborTenor*ForwardLiborSimulation!DP7) -> 0.0011397166
